Workbook

Sheet summary
A1: HMDAD 案例研究：代码输出、预测命中与文献验证总览
A2: 核心目的：先隐藏 Asthma / IBD 在 HMDAD 中的已知关联，再让 Full 模型对 292 个微生物重新打分排序；同时检查“已知关联能否被重新找回”以及“高排名预测能否被独立人体文献支持”。
A4: 1. 实验设置（代码实际运行配置） | F4: 一眼看结论
A5: 项目 | B5: 实际设置 | C5: 项目 | D5: 实际设置 | F5: 指标 | G5: Asthma | H5: IBD | I5: 怎么看 | J5: 结论
A6: 数据集 | B6: HMDAD | C6: 模型 | D6: Full | F6: Top10 严格人体文献确认 | G6: 10/10 | H6: 10/10 | I6: 100% / 100% | J6: 非常强
A7: 案例疾病 | B7: Asthma (ID=4); IBD (ID=23) | C7: 模式 | D7: reset_known | F7: Top50 严格人体文献确认 | G7: 30/50 | H7: 38/50 | I7: 60% / 76% | J7: 较强
A8: 候选微生物 | B8: 每个疾病 292 个 | C8: case repeats | D8: 10 | F8: Top50 广义人体证据支持 | G8: 44/50 | H8: 46/50 | I8: 88% / 92% | J8: 很强
A9: 随机种子 | B9: 2025–2034 | C9: 训练轮数 | D9: 300 epochs | F9: Top50 已知关联恢复 | G9: 6/9 | H9: 3/3 | I9: 66.7% / 100% | J9: IBD 全部找回
A10: 排序分数 | B10: 10 次预测概率的均值 | C10: 隐藏规则 | D10: 目标疾病整行关联隐藏且不参与正/负采样 | F10: Top10 中 HMDAD 未收录但被直接文献支持 | G10: 6/6 | H10: 8/8 | I10: 100% / 100% | J10: 最有价值
A12: 2. 代码输出：隐藏已知关联后，模型重新“命中/找回”了多少？
A13: Disease | B13: 原始已知关联 | C13: Top10 找回 | D13: Top10 命中率 | E13: Top20 找回 | F13: Top20 命中率 | G13: Top50 找回 | H13: Top50 命中率 | I13: 候选总数 | J13: 老师可直接理解的结论
A14: Asthma | B14: =E43 -> 9 | C14: =G43 -> 4 | D14: =C14/B14 -> 0.44444444 | E14: =H43 -> 6 | F14: =E14/B14 -> 0.66666667 | G14: =I43 -> 6 | H14: =G14/B14 -> 0.66666667 | I14: =F43 -> 292 | J14: Top50 内重新找回 6/9 条数据库已知关系，说明模型能恢复多数被隐藏关联。
A15: IBD | B15: =E44 -> 3 | C15: =G44 -> 2 | D15: =C15/B15 -> 0.66666667 | E15: =H44 -> 2 | F15: =E15/B15 -> 0.66666667 | G15: =I44 -> 3 | H15: =G15/B15 -> 1 | I15: =F44 -> 292 | J15: Top50 内重新找回 3/3 条数据库已知关系，全部恢复。
A17: 3. 预测结果：Top-K 预测有多少得到外部人体文献支持？
A18: Disease | B18: Top K | C18: 严格直接人体证据 | D18: 严格确认率 | E18: 直接+广义人体支持 | F18: 广义支持率 | G18: GATMDA 论文报告 | H18: 与 GATMDA 的关系 | I18: 是否可作为论文主结果 | J18: 说明
A19: Asthma | B19: 10 | C19: 10 | D19: =C19/B19 -> 1 | E19: 10 | F19: =E19/B19 -> 1 | G19: 10 | H19: 相同 | I19: 是 | J19: Top10 全部有直接人体文献支持。
A20: Asthma | B20: 20 | C20: 18 | D20: =C20/B20 -> 0.9 | E20: 19 | F20: =E20/B20 -> 0.95 | G20: 18 | H20: 严格确认数相同 | I20: 是 | J20: 严格口径 18/20；若计 broader 支持则 19/20。
A21: Asthma | B21: 50 | C21: 30 | D21: =C21/B21 -> 0.6 | E21: 44 | F21: =E21/B21 -> 0.88 | G21: 38 | H21: 严格口径更保守 | I21: 是 | J21: 30 条为直接人体证据；另有 14 条为较间接人体支持。
A22: IBD | B22: 10 | C22: 10 | D22: =C22/B22 -> 1 | E22: 10 | F22: =E22/B22 -> 1 | G22: 10 | H22: 相同 | I22: 是 | J22: Top10 全部有直接人体文献支持。
A23: IBD | B23: 20 | C23: 18 | D23: =C23/B23 -> 0.9 | E23: 20 | F23: =E23/B23 -> 1 | G23: 20 | H23: 严格口径更保守 | I23: 是 | J23: 18 条直接人体证据；其余 2 条有 broader 人体支持。
A24: IBD | B24: 50 | C24: 38 | D24: =C24/B24 -> 0.76 | E24: 46 | F24: =E24/B24 -> 0.92 | G24: 44 | H24: 严格确认 38；广义支持 46 | I24: 是 | J24: Top50 中 38 条直接人体证据，46 条至少有人体层面支持。
A26: 4. 最值得展示的结果：Top10 中 HMDAD 没收录的预测，外部文献是否支持？
A27: Disease | B27: Top10 总数 | C27: Top10 中 HMDAD 已知 | D27: Top10 中 HMDAD 未收录 | E27: 未收录中直接人体文献支持 | F27: 支持率 | G27: 如何理解 | H27: 论文表述建议 | I27: 注意事项 | J27: 数据来源
A28: Asthma | B28: 10 | C28: =COUNTIFS(Asthma_top50!$A$2:$A$51,"<=10",Asthma_top50!$G$2:$G$51,1) -> 4 | D28: =B28-C28 -> 6 | E28: =COUNTIFS(Asthma_top50!$A$2:$A$51,"<=10",Asthma_top50!$G$2:$G$51,0,Asthma_top50!$H$2:$H$51,"Confirmed (direct human)") -> 6 | F28: =E28/D28 -> 1 | G28: 数据库没告诉模型的 Top10 候选中，有 6 个；这 6 个全部能找到直接人体文献支持。 | H28: potential associations absent from HMDAD but supported by independent human studies | I28: 不能称为“全新发现”，因为文献已经存在。 | J28: Asthma_top50
A29: IBD | B29: 10 | C29: =COUNTIFS(IBD_top50!$A$2:$A$51,"<=10",IBD_top50!$G$2:$G$51,1) -> 2 | D29: =B29-C29 -> 8 | E29: =COUNTIFS(IBD_top50!$A$2:$A$51,"<=10",IBD_top50!$G$2:$G$51,0,IBD_top50!$H$2:$H$51,"Confirmed (direct human)") -> 8 | F29: =E29/D29 -> 1 | G29: 数据库没告诉模型的 Top10 候选中，有 8 个；这 8 个全部能找到直接人体文献支持。 | H29: potential associations absent from HMDAD but supported by independent human studies | I29: 不能称为“全新发现”，因为文献已经存在。 | J29: IBD_top50
A31: 5. 给老师的最终判断
A32: 结论 1 | B32: 代码运行是有效的：隐藏答案后，Asthma 的 9 条原有已知关联在 Top50 找回 6 条（66.7%）；IBD 的 3 条全部在 Top50 找回（100%）。
A33: 结论 2 | B33: 文献验证结果强：两种疾病 Top10 均达到 10/10 的严格人体文献确认；Top50 严格确认率为 Asthma 60%、IBD 76%。
A34: 结论 3 | B34: 如果把上/下位分类群、MR、疾病表型等较广义人体证据也纳入，Top50 支持率进一步达到 Asthma 88%、IBD 92%。
A35: 结论 4 | B35: 最有价值的是：Top10 中未被 HMDAD 收录的预测，Asthma 6/6、IBD 8/8 都有直接人体文献支持，说明模型能把数据库未标注但具有生物医学依据的候选排到前列。
A36: 总体评价 | B36: 案例研究结果是正面的，足以支撑论文中“模型不仅能恢复已知关联，也能优先排序出具有外部文献证据的潜在关联”这一结论。
A38: 术语说明：①“已知关联恢复/命中”只表示被隐藏的 HMDAD 已知关系重新进入 Top-K，不等于分类准确率；②“文献确认”表示外部人体研究支持该微生物与疾病存在关联；③ HMDAD 未收录 ≠ 生物学上全新发现，因此论文中应写 potential association，而非 novel discovery。
A40: 附录：原始代码 summary 输出（保留供复核）
A42: disease_id | B42: disease_name | C42: mode | D42: case_repeats | E42: original_known_count | F42: candidate_count | G42: top10_original_known_recovered | H42: top20_original_known_recovered | I42: top50_original_known_recovered | J42: mdmf_gate_mean | K42: mdmf_gate_std
A43: 4 | B43: Asthma | C43: reset_known | D43: 10 | E43: 9 | F43: 292 | G43: 4 | H43: 6 | I43: 6 | J43: 0.12281566 | K43: 0.00058379824
A44: 23 | B44: Inflammatory bowel disease(IBD) | C44: reset_known | D44: 10 | E44: 3 | F44: 292 | G44: 2 | H44: 2 | I44: 3 | J44: 0.1226173 | K44: 0.00038971462

Sheet config
A1: dataset | B1: case_study_mode | C1: target_disease_ids | D1: case_repeats | E1: seed_start | F1: epochs | G1: lr | H1: weight_decay | I1: feature_out | J1: hidden_size | K1: num_layers | L1: dropout | M1: drop_rate | N1: sim_threshold | O1: negative_multiplier | P1: alpha | Q1: beta | R1: mdmf_dim | S1: mdmf_loss_weight | T1: mdmf_gate_init | U1: model_variant | V1: ranking_score | W1: reset_known_training_rule
A2: HMDAD | B2: reset_known | C2: 4,23 | D2: 10 | E2: 2025 | F2: 300 | G2: 0.00025 | H2: 5e-05 | I2: 256 | J2: 128 | K2: 2 | L2: 0.5 | M2: 0.1 | N2: 0.2 | O2: 1 | P2: 1 | Q2: 0.25 | R2: 128 | S2: 0 | T2: -2 | U2: full | V2: mean predicted probability across 10 run(s) | W2: Target disease row is set to zero and excluded from positive/negative training sampling.

Sheet Asthma_top50
A1: rank | B1: microbe_index_0based | C1: microbe_id | D1: microbe_name | E1: score_mean | F1: score_std | G1: originally_known_in_HMDAD | H1: literature_status | I1: PMID_or_DOI | J1: evidence_notes | K1: source_url | L1: evidence_basis | M1: verification_scope
A2: 1 | B2: 108 | C2: 109 | D2: Clostridium difficile | E2: 0.66663946 | F2: 0.040839532 | G2: 0 | H2: Confirmed (direct human) | I2: 21872915; DOI 10.1016/j.jaci.2011.07.027 | J2: 婴儿期 C. difficile 定植与后续哮喘发生相关。 | K2: https://pubmed.ncbi.nlm.nih.gov/21872915/ | L2: Independent PubMed verification | M2: strict/direct
A3: 2 | B3: 4 | C3: 5 | D3: Actinobacteria | E3: 0.66428921 | F3: 0.035957907 | G3: 0 | H3: Confirmed (direct human) | I3: 26220531 | J3: 严重哮喘气道微生物组中 Actinobacteria 相关差异得到人体研究支持。 | K3: https://pubmed.ncbi.nlm.nih.gov/26220531/ | L3: Independent PubMed verification | M3: strict/direct
A4: 3 | B4: 106 | C4: 107 | D4: Clostridium coccoides | E4: 0.64931666 | F4: 0.03782492 | G4: 0 | H4: Confirmed (direct human) | I4: 21477358; DOI 10.1186/1471-2180-11-68 | J4: 婴儿粪便 C. coccoides subcluster XIVa 与后续哮喘风险指标相关。 | K4: https://pubmed.ncbi.nlm.nih.gov/21477358/ | L4: Independent PubMed verification | M4: strict/direct
A5: 4 | B5: 154 | C5: 155 | D5: Firmicutes | E5: 0.63764972 | F5: 0.089400513 | G5: 0 | H5: Confirmed (direct human) | I5: 27078029 | J5: 人体气道微生物组研究报道 Firmicutes 在哮喘/严重哮喘中发生改变。 | K5: https://pubmed.ncbi.nlm.nih.gov/27078029/ | L5: Independent PubMed verification | M5: strict/direct
A6: 5 | B6: 230 | C6: 231 | D6: Proteobacteria | E6: 0.63068555 | F6: 0.087391197 | G6: 1 | H6: Confirmed (direct human) | I6: 23265859; DOI 10.1016/j.jaci.2012.11.013 | J6: 成人活动性哮喘诱导痰中 Proteobacteria 显著增加。 | K6: https://pubmed.ncbi.nlm.nih.gov/23265859/ | L6: Independent PubMed verification | M6: strict/direct
A7: 6 | B7: 60 | C7: 61 | D7: Bacteroidetes | E7: 0.61443472 | F7: 0.06004263 | G7: 1 | H7: Confirmed (direct human) | I7: 27078029 | J7: 人体气道微生物组研究报道 Bacteroidetes 在哮喘中发生改变。 | K7: https://pubmed.ncbi.nlm.nih.gov/27078029/ | L7: Independent PubMed verification | M7: strict/direct
A8: 7 | B8: 224 | C8: 225 | D8: Prevotella | E8: 0.58545225 | F8: 0.092453475 | G8: 1 | H8: Confirmed (direct human) | I8: 27433177; DOI 10.4046/trd.2016.79.3.165 | J8: Steroid-naïve 哮喘患者痰液中 Prevotella 相关 OTU 与哮喘相关。 | K8: https://pubmed.ncbi.nlm.nih.gov/27433177/ | L8: Independent PubMed verification | M8: strict/direct
A9: 8 | B9: 168 | C9: 169 | D9: Helicobacter pylori | E9: 0.56569896 | F9: 0.094103343 | G9: 1 | H9: Confirmed (direct human) | I9: 18598192; DOI 10.1086/590158 | J9: H. pylori 定植与儿童哮喘呈负相关；负向关联同样属于 association。 | K9: https://pubmed.ncbi.nlm.nih.gov/18598192/ | L9: Independent PubMed verification | M9: strict/direct
A10: 9 | B10: 255 | C10: 256 | D10: Staphylococcus aureus | E10: 0.56123551 | F10: 0.099402834 | G10: 0 | H10: Confirmed (direct human) | I10: 25533526; DOI 10.1016/j.jaci.2014.10.052 | J10: S. aureus 定植与儿童/青年喘鸣和哮喘相关。 | K10: https://pubmed.ncbi.nlm.nih.gov/25533526/ | L10: Independent PubMed verification | M10: strict/direct
A11: 10 | B11: 93 | C11: 94 | D11: Clostridia | E11: 0.55970232 | F11: 0.074404294 | G11: 0 | H11: Confirmed (direct human) | I11: 36847620; DOI 10.1111/all.15691 | J11: 成人嗜酸粒细胞性哮喘研究观察到 commensal clostridia 改变。 | K11: https://pubmed.ncbi.nlm.nih.gov/36847620/ | L11: Independent PubMed verification | M11: strict/direct
A12: 11 | B12: 181 | C12: 182 | D12: Lachnospiraceae | E12: 0.50896649 | F12: 0.095583995 | G12: 0 | H12: Confirmed (direct human) | I12: 36847620; DOI 10.1111/all.15691 | J12: Lachnospiraceae 与哮喘 Type-2 炎症及肺功能变化相关。 | K12: https://pubmed.ncbi.nlm.nih.gov/36847620/ | L12: Independent PubMed verification | M12: strict/direct
A13: 12 | B13: 183 | C13: 184 | D13: Lactobacillus | E13: 0.50090459 | F13: 0.096522368 | G13: 0 | H13: Confirmed (direct human) | I13: 41266326 | J13: 人体研究报道 Lactobacillus 与哮喘状态相关（丰度降低）。 | K13: https://pubmed.ncbi.nlm.nih.gov/41266326/ | L13: Independent PubMed verification | M13: strict/direct
... A31: 30 | B31: 178 | C31: 179 | D31: Klebsiella pneumoniae | E31: 0.22138832 | F31: 0.06602884 | G31: 0 | H31: Supported (human broader/indirect) | I31: 36342141; GATMDA lead PMID 26953325 | J31: 成人哮喘患者来源的 K. pneumoniae 临床分离株有人体来源证据，但并非强病例-对照关联；GATMDA另给出 PMID 26953325。 | K31: https://pubmed.ncbi.nlm.nih.gov/36342141/ | L31: Human isolates + GATMDA lead | M31: broader/indirect
A32: 31 | B32: 250 | C32: 251 | D32: Shigella dysenteriae | E32: 0.22138831 | F32: 0.06602882 | G32: 0 | H32: Pending / no direct human evidence verified yet | J32: GATMDA Table 4 对 Shigella dysenteriae–asthma 标为 unconfirmed；当前未核实直接人体证据。 | L32: GATMDA Table 4: unconfirmed | M32: pending
A33: 32 | B33: 134 | C33: 135 | D33: Enterobacter aerogenes | E33: 0.22138831 | F33: 0.066028837 | G33: 0 | H33: Pending / no direct human evidence verified yet | I33: 23842440 | J33: 反查 GATMDA 所列 PMID 23842440：该文为 Fagonia olivieri 植物提取物/抗菌活性研究，并非 Enterobacter aerogenes–asthma 人体关联证据，故不能作为确认文献。 | K33: https://pubmed.ncbi.nlm.nih.gov/23842440/ | L33: Reverse-checked GATMDA lead; citation mismatch | M33: pending
A34: 33 | B34: 135 | C34: 136 | D34: Enterobacter hormaechei | E34: 0.22138831 | F34: 0.066028837 | G34: 0 | H34: Pending / no direct human evidence verified yet | J34: GATMDA Table 4 对 Enterobacter hormaechei–asthma 标为 unconfirmed。 | L34: GATMDA Table 4: unconfirmed | M34: pending
A35: 34 | B35: 118 | C35: 119 | D35: Coriobacteriaceae | E35: 0.22128101 | F35: 0.086977585 | G35: 0 | H35: Supported (human broader/indirect) | I35: 40826690 | J35: 双样本 Mendelian randomization 研究提示 Coriobacteriaceae 与 childhood asthma 风险存在因果关联；属于人群遗传证据，保守记为间接支持。 | K35: https://pubmed.ncbi.nlm.nih.gov/40826690/ | L35: Independent human MR evidence | M35: broader/indirect
A36: 35 | B36: 226 | C36: 227 | D36: Prevotellaceae | E36: 0.21493558 | F36: 0.085057539 | G36: 0 | H36: Confirmed (direct human) | I36: 34422359 | J36: 严重哮喘人体肠道研究报告 Prevotellaceae 与严重哮喘相关。 | K36: https://pubmed.ncbi.nlm.nih.gov/34422359/ | L36: Independent PubMed verification | M36: strict/direct
A37: 36 | B37: 119 | C37: 120 | D37: Corynebacterium | E37: 0.21217342 | F37: 0.087356768 | G37: 0 | H37: Confirmed (direct human) | I37: 31844063; DOI 10.1038/s41467-019-13698-x | J37: 儿童纵向研究中 Corynebacterium 丰度与严重哮喘急性加重呈负相关。 | K37: https://pubmed.ncbi.nlm.nih.gov/31844063/ | L37: Independent PubMed verification | M37: strict/direct
A38: 37 | B38: 177 | C38: 178 | D38: Klebsiella | E38: 0.20858404 | F38: 0.089456635 | G38: 0 | H38: Confirmed (direct human) | I38: 26220531 | J38: 严重哮喘气道研究中 Klebsiella 属成员显著增加。 | K38: https://pubmed.ncbi.nlm.nih.gov/26220531/ | L38: Independent PubMed verification | M38: strict/direct
A39: 38 | B39: 5 | C39: 6 | D39: Actinomyces | E39: 0.19898928 | F39: 0.061867895 | G39: 0 | H39: Confirmed (direct human) | I39: 37844548 | J39: 人体 steroid-naive asthma 诱导痰液研究中 Actinomyces 为丰富/特征性属之一，直接支持 Actinomyces–asthma 关联。 | K39: https://pubmed.ncbi.nlm.nih.gov/37844548/ | L39: Independent PubMed verification | M39: strict/direct
A40: 39 | B40: 139 | C40: 140 | D40: Enterococcus faecium | E40: 0.19822211 | F40: 0.049940254 | G40: 0 | H40: Supported (human broader/indirect) | I40: 41266326 | J40: 人体研究支持 Enterococcus 属/物种与哮喘相关，但当前未独立核实到 E. faecium 这一精确物种。 | K40: https://pubmed.ncbi.nlm.nih.gov/41266326/ | L40: Independent genus-level | M40: broader/indirect
A41: 40 | B41: 143 | C41: 144 | D41: Erysipelotrichales | E41: 0.19822211 | F41: 0.049940256 | G41: 0 | H41: Supported (human broader/indirect) | I41: 32598794; 35083405 | J41: 人体 bronchial asthma 肠道微生物研究报告 Erysipelotrichaceae/Erysipelotrichia 改变，可对上一级 Erysipelotrichales 提供分类学间接支持。 | K41: https://pubmed.ncbi.nlm.nih.gov/32598794/ | L41: Independent human study; adjacent taxonomic-level support | M41: broader/indirect
A42: 41 | B42: 222 | C42: 223 | D42: Porphyromonas gingivalis | E42: 0.18921879 | F42: 0.059952145 | G42: 0 | H42: Confirmed (direct human) | I42: 17088145; DOI 10.1016/j.jaci.2006.07.029 | J42: 人群研究中 P. gingivalis 血清反应与当前哮喘患病率呈负相关。 | K42: https://pubmed.ncbi.nlm.nih.gov/17088145/ | L42: Independent PubMed verification | M42: strict/direct
A43: 42 | B43: 247 | C43: 248 | D43: Selenomonas | E43: 0.18921879 | F43: 0.059952152 | G43: 0 | H43: Supported (human broader/indirect) | I43: 32778700; GATMDA lead PMID 27093794 | J43: 儿童哮喘相关队列中 Selenomonas 与过敏/IgE 表型相关；GATMDA另给出 PMID 27093794。 | K43: https://pubmed.ncbi.nlm.nih.gov/32778700/ | L43: Independent phenotype-level + GATMDA lead | M43: broader/indirect
A44: 43 | B44: 229 | C44: 230 | D44: Propionibacterium acnes | E44: 0.18725162 | F44: 0.050625155 | G44: 0 | H44: Confirmed (direct human) | I44: 27433177 | J44: 人体哮喘痰液研究报告 Propionibacterium acnes 相关 OTU 在哮喘组更常见。 | K44: https://pubmed.ncbi.nlm.nih.gov/27433177/ | L44: Independent PubMed verification | M44: strict/direct
A45: 44 | B45: 228 | C45: 229 | D45: Propionibacterium | E45: 0.18725162 | F45: 0.050625155 | G45: 0 | H45: Supported (human broader/indirect) | I45: 27433177; GATMDA lead PMID 13268970 | J45: P. acnes 的人体哮喘证据可支持 Propionibacterium 属层面；GATMDA另列 PMID 13268970。 | K45: https://pubmed.ncbi.nlm.nih.gov/27433177/ | L45: Species-to-genus support + GATMDA lead | M45: broader/indirect
A46: 45 | B46: 233 | C46: 234 | D46: Rickettsiales | E46: 0.18502099 | F46: 0.058677825 | G46: 0 | H46: Supported (human broader/indirect) | I46: 26627545 | J46: 人体哮喘气道微生物组研究中 Rickettsia 相关分类群在 asthmatics 中富集；对 Rickettsiales 目级预测属于下位分类群支持，故记为间接证据。 | K46: https://pubmed.ncbi.nlm.nih.gov/26627545/ | L46: Independent human study; lower-taxon support | M46: broader/indirect
A47: 46 | B47: 190 | C47: 191 | D47: Lysobacter | E47: 0.18502099 | F47: 0.058677813 | G47: 0 | H47: Pending / no direct human evidence verified yet | J47: 当前未核实 Lysobacter 与哮喘的直接人体关联。 | L47: Pending | M47: pending
A48: 47 | B48: 194 | C48: 195 | D48: Methanobrevibacter smithii | E48: 0.18282896 | F48: 0.056288616 | G48: 0 | H48: Confirmed (direct human) | I48: 30208875; DOI 10.1186/s12866-018-1257-x | J48: UK 成人 asthma metagenome-wide association study 直接比较 asthma 与 healthy controls，Methanobrevibacter smithii 在健康对照中的丰度更高，即在 asthma 中相对降低，属于直接人体关联。 | K48: https://pubmed.ncbi.nlm.nih.gov/30208875/ | L48: Independent PubMed verification | M48: strict/direct
A49: 48 | B49: 142 | C49: 143 | D49: Erysipelotrichaceae | E49: 0.18282896 | F49: 0.056288619 | G49: 0 | H49: Confirmed (direct human) | I49: 32598794; 35083405 | J49: 人体 bronchial asthma/UC/IBS 微生物组研究明确报告 Erysipelotrichaceae 家族在 bronchial asthma 人群中的组成变化，构成精确家族级人体证据。 | K49: https://pubmed.ncbi.nlm.nih.gov/32598794/ | L49: Independent PubMed verification | M49: strict/direct
A50: 49 | B50: 256 | C50: 257 | D50: Staphylococcus epidermidis | E50: 0.18062849 | F50: 0.053809998 | G50: 0 | H50: Supported (human broader/indirect) | I50: 33592204 | J50: 哮喘相关鼻腔微生物组研究中 S. epidermidis 与致敏/炎症表型相关，非直接病例-对照效应。 | K50: https://pubmed.ncbi.nlm.nih.gov/33592204/ | L50: Independent phenotype-level | M50: broader/indirect
A51: 50 | B51: 128 | C51: 129 | D51: Dietzia maris | E51: 0.18062848 | F51: 0.053810005 | G51: 0 | H51: Pending / no direct human evidence verified yet | J51: 当前未核实 Dietzia maris 与哮喘的直接人体关联。 | L51: Pending | M51: pending

Sheet Asthma_all
A1: rank | B1: microbe_index_0based | C1: microbe_id | D1: microbe_name | E1: score_mean | F1: score_std | G1: originally_known_in_HMDAD | H1: literature_status | I1: PMID_or_DOI | J1: evidence_notes | K1: source_url | L1: evidence_basis | M1: verification_scope
A2: 1 | B2: 108 | C2: 109 | D2: Clostridium difficile | E2: 0.66663946 | F2: 0.040839532 | G2: 0 | H2: Confirmed (direct human) | I2: 21872915; DOI 10.1016/j.jaci.2011.07.027 | J2: 婴儿期 C. difficile 定植与后续哮喘发生相关。 | K2: https://pubmed.ncbi.nlm.nih.gov/21872915/ | L2: Independent PubMed verification | M2: strict/direct
A3: 2 | B3: 4 | C3: 5 | D3: Actinobacteria | E3: 0.66428921 | F3: 0.035957907 | G3: 0 | H3: Confirmed (direct human) | I3: 26220531 | J3: 严重哮喘气道微生物组中 Actinobacteria 相关差异得到人体研究支持。 | K3: https://pubmed.ncbi.nlm.nih.gov/26220531/ | L3: Independent PubMed verification | M3: strict/direct
A4: 3 | B4: 106 | C4: 107 | D4: Clostridium coccoides | E4: 0.64931666 | F4: 0.03782492 | G4: 0 | H4: Confirmed (direct human) | I4: 21477358; DOI 10.1186/1471-2180-11-68 | J4: 婴儿粪便 C. coccoides subcluster XIVa 与后续哮喘风险指标相关。 | K4: https://pubmed.ncbi.nlm.nih.gov/21477358/ | L4: Independent PubMed verification | M4: strict/direct
A5: 4 | B5: 154 | C5: 155 | D5: Firmicutes | E5: 0.63764972 | F5: 0.089400513 | G5: 0 | H5: Confirmed (direct human) | I5: 27078029 | J5: 人体气道微生物组研究报道 Firmicutes 在哮喘/严重哮喘中发生改变。 | K5: https://pubmed.ncbi.nlm.nih.gov/27078029/ | L5: Independent PubMed verification | M5: strict/direct
A6: 5 | B6: 230 | C6: 231 | D6: Proteobacteria | E6: 0.63068555 | F6: 0.087391197 | G6: 1 | H6: Confirmed (direct human) | I6: 23265859; DOI 10.1016/j.jaci.2012.11.013 | J6: 成人活动性哮喘诱导痰中 Proteobacteria 显著增加。 | K6: https://pubmed.ncbi.nlm.nih.gov/23265859/ | L6: Independent PubMed verification | M6: strict/direct
A7: 6 | B7: 60 | C7: 61 | D7: Bacteroidetes | E7: 0.61443472 | F7: 0.06004263 | G7: 1 | H7: Confirmed (direct human) | I7: 27078029 | J7: 人体气道微生物组研究报道 Bacteroidetes 在哮喘中发生改变。 | K7: https://pubmed.ncbi.nlm.nih.gov/27078029/ | L7: Independent PubMed verification | M7: strict/direct
A8: 7 | B8: 224 | C8: 225 | D8: Prevotella | E8: 0.58545225 | F8: 0.092453475 | G8: 1 | H8: Confirmed (direct human) | I8: 27433177; DOI 10.4046/trd.2016.79.3.165 | J8: Steroid-naïve 哮喘患者痰液中 Prevotella 相关 OTU 与哮喘相关。 | K8: https://pubmed.ncbi.nlm.nih.gov/27433177/ | L8: Independent PubMed verification | M8: strict/direct
A9: 8 | B9: 168 | C9: 169 | D9: Helicobacter pylori | E9: 0.56569896 | F9: 0.094103343 | G9: 1 | H9: Confirmed (direct human) | I9: 18598192; DOI 10.1086/590158 | J9: H. pylori 定植与儿童哮喘呈负相关；负向关联同样属于 association。 | K9: https://pubmed.ncbi.nlm.nih.gov/18598192/ | L9: Independent PubMed verification | M9: strict/direct
A10: 9 | B10: 255 | C10: 256 | D10: Staphylococcus aureus | E10: 0.56123551 | F10: 0.099402834 | G10: 0 | H10: Confirmed (direct human) | I10: 25533526; DOI 10.1016/j.jaci.2014.10.052 | J10: S. aureus 定植与儿童/青年喘鸣和哮喘相关。 | K10: https://pubmed.ncbi.nlm.nih.gov/25533526/ | L10: Independent PubMed verification | M10: strict/direct
A11: 10 | B11: 93 | C11: 94 | D11: Clostridia | E11: 0.55970232 | F11: 0.074404294 | G11: 0 | H11: Confirmed (direct human) | I11: 36847620; DOI 10.1111/all.15691 | J11: 成人嗜酸粒细胞性哮喘研究观察到 commensal clostridia 改变。 | K11: https://pubmed.ncbi.nlm.nih.gov/36847620/ | L11: Independent PubMed verification | M11: strict/direct
A12: 11 | B12: 181 | C12: 182 | D12: Lachnospiraceae | E12: 0.50896649 | F12: 0.095583995 | G12: 0 | H12: Confirmed (direct human) | I12: 36847620; DOI 10.1111/all.15691 | J12: Lachnospiraceae 与哮喘 Type-2 炎症及肺功能变化相关。 | K12: https://pubmed.ncbi.nlm.nih.gov/36847620/ | L12: Independent PubMed verification | M12: strict/direct
A13: 12 | B13: 183 | C13: 184 | D13: Lactobacillus | E13: 0.50090459 | F13: 0.096522368 | G13: 0 | H13: Confirmed (direct human) | I13: 41266326 | J13: 人体研究报道 Lactobacillus 与哮喘状态相关（丰度降低）。 | K13: https://pubmed.ncbi.nlm.nih.gov/41266326/ | L13: Independent PubMed verification | M13: strict/direct
... A31: 30 | B31: 178 | C31: 179 | D31: Klebsiella pneumoniae | E31: 0.22138832 | F31: 0.06602884 | G31: 0 | H31: Supported (human broader/indirect) | I31: 36342141; GATMDA lead PMID 26953325 | J31: 成人哮喘患者来源的 K. pneumoniae 临床分离株有人体来源证据，但并非强病例-对照关联；GATMDA另给出 PMID 26953325。 | K31: https://pubmed.ncbi.nlm.nih.gov/36342141/ | L31: Human isolates + GATMDA lead | M31: broader/indirect
A32: 31 | B32: 250 | C32: 251 | D32: Shigella dysenteriae | E32: 0.22138831 | F32: 0.06602882 | G32: 0 | H32: Pending / no direct human evidence verified yet | J32: GATMDA Table 4 对 Shigella dysenteriae–asthma 标为 unconfirmed；当前未核实直接人体证据。 | L32: GATMDA Table 4: unconfirmed | M32: pending
A33: 32 | B33: 134 | C33: 135 | D33: Enterobacter aerogenes | E33: 0.22138831 | F33: 0.066028837 | G33: 0 | H33: Pending / no direct human evidence verified yet | I33: 23842440 | J33: 反查 GATMDA 所列 PMID 23842440：该文为 Fagonia olivieri 植物提取物/抗菌活性研究，并非 Enterobacter aerogenes–asthma 人体关联证据，故不能作为确认文献。 | K33: https://pubmed.ncbi.nlm.nih.gov/23842440/ | L33: Reverse-checked GATMDA lead; citation mismatch | M33: pending
A34: 33 | B34: 135 | C34: 136 | D34: Enterobacter hormaechei | E34: 0.22138831 | F34: 0.066028837 | G34: 0 | H34: Pending / no direct human evidence verified yet | J34: GATMDA Table 4 对 Enterobacter hormaechei–asthma 标为 unconfirmed。 | L34: GATMDA Table 4: unconfirmed | M34: pending
A35: 34 | B35: 118 | C35: 119 | D35: Coriobacteriaceae | E35: 0.22128101 | F35: 0.086977585 | G35: 0 | H35: Supported (human broader/indirect) | I35: 40826690 | J35: 双样本 Mendelian randomization 研究提示 Coriobacteriaceae 与 childhood asthma 风险存在因果关联；属于人群遗传证据，保守记为间接支持。 | K35: https://pubmed.ncbi.nlm.nih.gov/40826690/ | L35: Independent human MR evidence | M35: broader/indirect
A36: 35 | B36: 226 | C36: 227 | D36: Prevotellaceae | E36: 0.21493558 | F36: 0.085057539 | G36: 0 | H36: Confirmed (direct human) | I36: 34422359 | J36: 严重哮喘人体肠道研究报告 Prevotellaceae 与严重哮喘相关。 | K36: https://pubmed.ncbi.nlm.nih.gov/34422359/ | L36: Independent PubMed verification | M36: strict/direct
A37: 36 | B37: 119 | C37: 120 | D37: Corynebacterium | E37: 0.21217342 | F37: 0.087356768 | G37: 0 | H37: Confirmed (direct human) | I37: 31844063; DOI 10.1038/s41467-019-13698-x | J37: 儿童纵向研究中 Corynebacterium 丰度与严重哮喘急性加重呈负相关。 | K37: https://pubmed.ncbi.nlm.nih.gov/31844063/ | L37: Independent PubMed verification | M37: strict/direct
A38: 37 | B38: 177 | C38: 178 | D38: Klebsiella | E38: 0.20858404 | F38: 0.089456635 | G38: 0 | H38: Confirmed (direct human) | I38: 26220531 | J38: 严重哮喘气道研究中 Klebsiella 属成员显著增加。 | K38: https://pubmed.ncbi.nlm.nih.gov/26220531/ | L38: Independent PubMed verification | M38: strict/direct
A39: 38 | B39: 5 | C39: 6 | D39: Actinomyces | E39: 0.19898928 | F39: 0.061867895 | G39: 0 | H39: Confirmed (direct human) | I39: 37844548 | J39: 人体 steroid-naive asthma 诱导痰液研究中 Actinomyces 为丰富/特征性属之一，直接支持 Actinomyces–asthma 关联。 | K39: https://pubmed.ncbi.nlm.nih.gov/37844548/ | L39: Independent PubMed verification | M39: strict/direct
A40: 39 | B40: 139 | C40: 140 | D40: Enterococcus faecium | E40: 0.19822211 | F40: 0.049940254 | G40: 0 | H40: Supported (human broader/indirect) | I40: 41266326 | J40: 人体研究支持 Enterococcus 属/物种与哮喘相关，但当前未独立核实到 E. faecium 这一精确物种。 | K40: https://pubmed.ncbi.nlm.nih.gov/41266326/ | L40: Independent genus-level | M40: broader/indirect
A41: 40 | B41: 143 | C41: 144 | D41: Erysipelotrichales | E41: 0.19822211 | F41: 0.049940256 | G41: 0 | H41: Supported (human broader/indirect) | I41: 32598794; 35083405 | J41: 人体 bronchial asthma 肠道微生物研究报告 Erysipelotrichaceae/Erysipelotrichia 改变，可对上一级 Erysipelotrichales 提供分类学间接支持。 | K41: https://pubmed.ncbi.nlm.nih.gov/32598794/ | L41: Independent human study; adjacent taxonomic-level support | M41: broader/indirect
A42: 41 | B42: 222 | C42: 223 | D42: Porphyromonas gingivalis | E42: 0.18921879 | F42: 0.059952145 | G42: 0 | H42: Confirmed (direct human) | I42: 17088145; DOI 10.1016/j.jaci.2006.07.029 | J42: 人群研究中 P. gingivalis 血清反应与当前哮喘患病率呈负相关。 | K42: https://pubmed.ncbi.nlm.nih.gov/17088145/ | L42: Independent PubMed verification | M42: strict/direct
A43: 42 | B43: 247 | C43: 248 | D43: Selenomonas | E43: 0.18921879 | F43: 0.059952152 | G43: 0 | H43: Supported (human broader/indirect) | I43: 32778700; GATMDA lead PMID 27093794 | J43: 儿童哮喘相关队列中 Selenomonas 与过敏/IgE 表型相关；GATMDA另给出 PMID 27093794。 | K43: https://pubmed.ncbi.nlm.nih.gov/32778700/ | L43: Independent phenotype-level + GATMDA lead | M43: broader/indirect
A44: 43 | B44: 229 | C44: 230 | D44: Propionibacterium acnes | E44: 0.18725162 | F44: 0.050625155 | G44: 0 | H44: Confirmed (direct human) | I44: 27433177 | J44: 人体哮喘痰液研究报告 Propionibacterium acnes 相关 OTU 在哮喘组更常见。 | K44: https://pubmed.ncbi.nlm.nih.gov/27433177/ | L44: Independent PubMed verification | M44: strict/direct
A45: 44 | B45: 228 | C45: 229 | D45: Propionibacterium | E45: 0.18725162 | F45: 0.050625155 | G45: 0 | H45: Supported (human broader/indirect) | I45: 27433177; GATMDA lead PMID 13268970 | J45: P. acnes 的人体哮喘证据可支持 Propionibacterium 属层面；GATMDA另列 PMID 13268970。 | K45: https://pubmed.ncbi.nlm.nih.gov/27433177/ | L45: Species-to-genus support + GATMDA lead | M45: broader/indirect
A46: 45 | B46: 233 | C46: 234 | D46: Rickettsiales | E46: 0.18502099 | F46: 0.058677825 | G46: 0 | H46: Supported (human broader/indirect) | I46: 26627545 | J46: 人体哮喘气道微生物组研究中 Rickettsia 相关分类群在 asthmatics 中富集；对 Rickettsiales 目级预测属于下位分类群支持，故记为间接证据。 | K46: https://pubmed.ncbi.nlm.nih.gov/26627545/ | L46: Independent human study; lower-taxon support | M46: broader/indirect
A47: 46 | B47: 190 | C47: 191 | D47: Lysobacter | E47: 0.18502099 | F47: 0.058677813 | G47: 0 | H47: Pending / no direct human evidence verified yet | J47: 当前未核实 Lysobacter 与哮喘的直接人体关联。 | L47: Pending | M47: pending
A48: 47 | B48: 194 | C48: 195 | D48: Methanobrevibacter smithii | E48: 0.18282896 | F48: 0.056288616 | G48: 0 | H48: Confirmed (direct human) | I48: 30208875; DOI 10.1186/s12866-018-1257-x | J48: UK 成人 asthma metagenome-wide association study 直接比较 asthma 与 healthy controls，Methanobrevibacter smithii 在健康对照中的丰度更高，即在 asthma 中相对降低，属于直接人体关联。 | K48: https://pubmed.ncbi.nlm.nih.gov/30208875/ | L48: Independent PubMed verification | M48: strict/direct
A49: 48 | B49: 142 | C49: 143 | D49: Erysipelotrichaceae | E49: 0.18282896 | F49: 0.056288619 | G49: 0 | H49: Confirmed (direct human) | I49: 32598794; 35083405 | J49: 人体 bronchial asthma/UC/IBS 微生物组研究明确报告 Erysipelotrichaceae 家族在 bronchial asthma 人群中的组成变化，构成精确家族级人体证据。 | K49: https://pubmed.ncbi.nlm.nih.gov/32598794/ | L49: Independent PubMed verification | M49: strict/direct
A50: 49 | B50: 256 | C50: 257 | D50: Staphylococcus epidermidis | E50: 0.18062849 | F50: 0.053809998 | G50: 0 | H50: Supported (human broader/indirect) | I50: 33592204 | J50: 哮喘相关鼻腔微生物组研究中 S. epidermidis 与致敏/炎症表型相关，非直接病例-对照效应。 | K50: https://pubmed.ncbi.nlm.nih.gov/33592204/ | L50: Independent phenotype-level | M50: broader/indirect
A51: 50 | B51: 128 | C51: 129 | D51: Dietzia maris | E51: 0.18062848 | F51: 0.053810005 | G51: 0 | H51: Pending / no direct human evidence verified yet | J51: 当前未核实 Dietzia maris 与哮喘的直接人体关联。 | L51: Pending | M51: pending
A52: 51 | B52: 160 | C52: 161 | D52: Fusobacterium nucleatum | E52: 0.17246367 | F52: 0.046711335 | G52: 0
A53: 52 | B53: 120 | C53: 121 | D53: Coxiellaceae | E53: 0.16813012 | F53: 0.057765674 | G53: 0
A54: 53 | B54: 125 | C54: 126 | D54: Desulfovibrio | E54: 0.16749935 | F54: 0.047181302 | G54: 0
A55: 54 | B55: 220 | C55: 221 | D55: Porphyromonadaceae | E55: 0.16494014 | F55: 0.061219927 | G55: 0
A56: 55 | B56: 205 | C56: 206 | D56: Oxalobacter formigenes | E56: 0.162711 | F56: 0.048134542 | G56: 0
A57: 56 | B57: 62 | C57: 63 | D57: Bifidobacterium | E57: 0.16123582 | F57: 0.067857453 | G57: 0
...

Sheet IBD_top50
A1: rank | B1: microbe_index_0based | C1: microbe_id | D1: microbe_name | E1: score_mean | F1: score_std | G1: originally_known_in_HMDAD | H1: literature_status | I1: PMID_or_DOI | J1: evidence_notes | K1: source_url | L1: evidence_basis | M1: verification_scope
A2: 1 | B2: 108 | C2: 109 | D2: Clostridium difficile | E2: 0.64931703 | F2: 0.063818269 | G2: 0 | H2: Confirmed (direct human) | I2: 18513271 | J2: IBD 人群中 C. difficile 感染/定植显著相关，尤其在 UC 中常见。 | K2: https://pubmed.ncbi.nlm.nih.gov/18513271/ | L2: Independent PubMed verification | M2: strict/direct
A3: 2 | B3: 106 | C3: 107 | D3: Clostridium coccoides | E3: 0.63173096 | F3: 0.058970483 | G3: 0 | H3: Confirmed (direct human) | I3: 22092917; GATMDA lead PMID 19235886 | J3: 人体 IBD/UC 研究报告 C. coccoides group 明显减少。 | K3: https://pubmed.ncbi.nlm.nih.gov/22092917/ | L3: Independent PubMed verification + GATMDA lead | M3: strict/direct
A4: 3 | B4: 60 | C4: 61 | D4: Bacteroidetes | E4: 0.61293416 | F4: 0.057358029 | G4: 0 | H4: Confirmed (direct human) | I4: 33738265 | J4: IBD 人体肠道宏基因组研究报道 Bacteroidetes 组成显著改变。 | K4: https://pubmed.ncbi.nlm.nih.gov/33738265/ | L4: Independent PubMed verification | M4: strict/direct
A5: 4 | B5: 4 | C5: 5 | D5: Actinobacteria | E5: 0.58516245 | F5: 0.06589116 | G5: 1 | H5: Confirmed (direct human) | I5: 33738265 | J5: IBD 人体肠道宏基因组研究支持 Actinobacteria 组成变化。 | K5: https://pubmed.ncbi.nlm.nih.gov/33738265/ | L5: Independent PubMed verification | M5: strict/direct
A6: 5 | B6: 93 | C6: 94 | D6: Clostridia | E6: 0.5297197 | F6: 0.046664697 | G6: 0 | H6: Confirmed (direct human) | I6: 31142855 | J6: 纵向 multi-omics 人体 IBD 研究显示疾病活动伴随 clostridia 的系统性分子/群落扰动，直接支持 Clostridia–IBD 关联。 | K6: https://pubmed.ncbi.nlm.nih.gov/31142855/ | L6: Independent PubMed verification | M6: strict/direct
A7: 6 | B7: 154 | C7: 155 | D7: Firmicutes | E7: 0.50680436 | F7: 0.11248417 | G7: 0 | H7: Confirmed (direct human) | I7: 33738265; GATMDA lead PMID 25307765 | J7: IBD 人体研究中 Firmicutes 显著改变；GATMDA Table 5 也给出 PMID 25307765。 | K7: https://pubmed.ncbi.nlm.nih.gov/33738265/ | L7: Independent PubMed verification + GATMDA lead | M7: strict/direct
A8: 7 | B8: 230 | C8: 231 | D8: Proteobacteria | E8: 0.49374721 | F8: 0.11887946 | G8: 1 | H8: Confirmed (direct human) | I8: 33738265 | J8: IBD 人体肠道研究支持 Proteobacteria 增加/失衡。 | K8: https://pubmed.ncbi.nlm.nih.gov/33738265/ | L8: Independent PubMed verification | M8: strict/direct
A9: 8 | B9: 224 | C9: 225 | D9: Prevotella | E9: 0.47112395 | F9: 0.11208429 | G9: 0 | H9: Confirmed (direct human) | I9: 34620880; GATMDA lead PMID 25307765 | J9: 人体 IBD 数据显示 Prevotella 组成与 IBD 状态相关。 | K9: https://pubmed.ncbi.nlm.nih.gov/34620880/ | L9: Independent PubMed verification + GATMDA lead | M9: strict/direct
A10: 9 | B10: 168 | C10: 169 | D10: Helicobacter pylori | E10: 0.46937895 | F10: 0.11407409 | G10: 0 | H10: Confirmed (direct human) | I10: 37682136; GATMDA lead PMID 22221289 | J10: 人体研究支持 H. pylori 与 IBD 的负向/保护性关联；负向也属于 association。 | K10: https://pubmed.ncbi.nlm.nih.gov/37682136/ | L10: Independent PubMed verification + GATMDA lead | M10: strict/direct
A11: 10 | B11: 110 | C11: 111 | D11: Clostridium leptum | E11: 0.46524679 | F11: 0.077642731 | G11: 0 | H11: Confirmed (direct human) | I11: 22092917; GATMDA lead PMID 28099495 | J11: 人体 IBD/UC 研究报告 C. leptum group 减少。 | K11: https://pubmed.ncbi.nlm.nih.gov/22092917/ | L11: Independent PubMed verification + GATMDA lead | M11: strict/direct
A12: 11 | B12: 255 | C12: 256 | D12: Staphylococcus aureus | E12: 0.42097209 | F12: 0.11661842 | G12: 0 | H12: Confirmed (direct human) | I12: 11424320 | J12: IBD 患者肠黏膜中检测到 S. aureus，并与疾病状态相关。 | K12: https://pubmed.ncbi.nlm.nih.gov/11424320/ | L12: Independent PubMed verification | M12: strict/direct
A13: 12 | B13: 68 | C13: 69 | D13: Burkholderia | E13: 0.39792757 | F13: 0.093858679 | G13: 0 | H13: Confirmed (direct human) | I13: 39187879 | J13: UC 人体纵向研究中 Burkholderia-Caballeronia-Paraburkholderia 与疾病/缓解状态相关。 | K13: https://pubmed.ncbi.nlm.nih.gov/39187879/ | L13: Independent PubMed verification | M13: strict/direct
... A30: 29 | B30: 2 | C30: 3 | D30: Acinetobacter | E30: 0.21503316 | F30: 0.054474599 | G30: 0 | H30: Confirmed (direct human) | I30: 25559083 | J30: 人体 colitis 组织研究发现 Acinetobacter 等菌在 actively inflamed colitis tissue 中富集，属于直接人体 IBD/colitis 关联证据。 | K30: https://pubmed.ncbi.nlm.nih.gov/25559083/ | L30: Independent PubMed verification | M30: strict/direct
A31: 30 | B31: 120 | C31: 121 | D31: Coxiellaceae | E31: 0.19113614 | F31: 0.045546413 | G31: 0 | H31: Pending / no direct human evidence verified yet | J31: 当前未独立核实 Coxiellaceae 与 IBD 的直接人体关联。 | L31: Pending | M31: pending
A32: 31 | B32: 5 | C32: 6 | D32: Actinomyces | E32: 0.18773857 | F32: 0.065629591 | G32: 0 | H32: Confirmed (direct human) | I32: 30545401 | J32: 人体病例-对照肠道微生物研究比较 Crohn's disease、UC 与健康对照，Actinomyces 在疾病队列中显著改变，直接支持该关联。 | K32: https://pubmed.ncbi.nlm.nih.gov/30545401/ | L32: Independent PubMed verification | M32: strict/direct
A33: 32 | B33: 159 | C33: 160 | D33: Fusobacterium | E33: 0.1785091 | F33: 0.057557866 | G33: 0 | H33: Confirmed (direct human) | I33: 39273567; GATMDA lead PMID 25307765 | J33: 人体 IBD 微生物组研究支持 Fusobacterium 与疾病相关；GATMDA Table 5 也列出证据。 | K33: https://pubmed.ncbi.nlm.nih.gov/39273567/ | L33: Independent PubMed verification + GATMDA lead | M33: strict/direct
A34: 33 | B34: 114 | C34: 115 | D34: Collinsella aerofaciens | E34: 0.17718287 | F34: 0.04004577 | G34: 0 | H34: Supported (human broader/indirect) | I34: 21209126 | J34: Crohn's disease、未患病一级亲属及健康对照的人体研究检测到 Collinsella aerofaciens 差异，但主要信号出现在未患病亲属而非直接 CD 病例效应，因此保守记为间接支持。 | K34: https://pubmed.ncbi.nlm.nih.gov/21209126/ | L34: Independent human study; indirect disease-context evidence | M34: broader/indirect
A35: 34 | B35: 153 | C35: 154 | D35: Faecalibacterium prausnitzii | E35: 0.1670976 | F35: 0.071529776 | G35: 0 | H35: Confirmed (direct human) | I35: 18936492 | J35: 经典 Crohn's disease 人体研究显示 Faecalibacterium prausnitzii 在患者中减少，并与术后复发相关，构成直接人体证据。 | K35: https://pubmed.ncbi.nlm.nih.gov/18936492/ | L35: Independent PubMed verification | M35: strict/direct
A36: 35 | B36: 62 | C36: 63 | D36: Bifidobacterium | E36: 0.16025481 | F36: 0.05786736 | G36: 0 | H36: Confirmed (direct human) | I36: 38779566; GATMDA lead PMID 24478468 | J36: UC 与健康对照研究中 Bifidobacterium 显著改变。 | K36: https://pubmed.ncbi.nlm.nih.gov/38779566/ | L36: Independent PubMed verification + GATMDA lead | M36: strict/direct
A37: 36 | B37: 161 | C37: 162 | D37: Gammaproteobacteria | E37: 0.15023371 | F37: 0.054084768 | G37: 0 | H37: Supported (human broader/indirect) | I37: 33738265 | J37: IBD 人体研究支持 Proteobacteria/Gammaproteobacteria 相关失衡；对该精确 class 的效应保守记为 broader。 | K37: https://pubmed.ncbi.nlm.nih.gov/33738265/ | L37: Independent broader taxon | M37: broader/indirect
A38: 37 | B38: 226 | C38: 227 | D38: Prevotellaceae | E38: 0.13810329 | F38: 0.059789613 | G38: 0 | H38: Supported (human broader/indirect) | I38: 39806416 | J38: 人体 IBD 研究支持 Prevotellaceae 相关菌群/代谢轴与 IBD 相关，证据偏机制/关联链条。 | K38: https://pubmed.ncbi.nlm.nih.gov/39806416/ | L38: Independent human broader evidence | M38: broader/indirect
A39: 38 | B39: 262 | C39: 263 | D39: Streptococcus mitis | E39: 0.13710661 | F39: 0.050481713 | G39: 0 | H39: Confirmed (direct human) | I39: 40854688 | J39: UC 人体黏膜微生物组研究中，吸烟与 Streptococcus mitis 等口源菌在结肠黏膜的异位增加相关，属于 IBD 疾病背景下的精确物种人体证据。 | K39: https://pubmed.ncbi.nlm.nih.gov/40854688/ | L39: Independent PubMed verification | M39: strict/direct
A40: 39 | B40: 250 | C40: 251 | D40: Shigella dysenteriae | E40: 0.13304512 | F40: 0.043353917 | G40: 0 | H40: Pending / no direct human evidence verified yet | J40: GATMDA Table 5 对 Shigella dysenteriae–IBD 标为 unconfirmed。 | L40: GATMDA Table 5: unconfirmed | M40: pending
A41: 40 | B41: 178 | C41: 179 | D41: Klebsiella pneumoniae | E41: 0.13304511 | F41: 0.043353899 | G41: 0 | H41: Confirmed (direct human) | I41: 36436756 | J41: 人体 UC 样本中 Klebsiella pneumoniae 与 Mayo disease activity index 呈正相关，并从 colitis 患者结肠组织分离菌株；后续机制实验进一步验证其致炎作用。 | K41: https://pubmed.ncbi.nlm.nih.gov/36436756/ | L41: Independent human + mechanistic verification | M41: strict/direct
A42: 41 | B42: 135 | C42: 136 | D42: Enterobacter hormaechei | E42: 0.13304511 | F42: 0.043353901 | G42: 0 | H42: Supported (human broader/indirect) | I42: 22837318 | J42: 新诊断儿童 Crohn's disease 人体病例-对照研究检测到 Enterobacter hormaechei，病例检出率高于对照但未达到传统显著性（P≈0.059），故记为人体间接/趋势性支持。 | K42: https://pubmed.ncbi.nlm.nih.gov/22837318/ | L42: Independent human study; non-significant trend | M42: broader/indirect
A43: 42 | B43: 134 | C43: 135 | D43: Enterobacter aerogenes | E43: 0.13304511 | F43: 0.043353901 | G43: 0 | H43: Pending / no direct human evidence verified yet | I43: 4061480 | J43: 反查 GATMDA 所列 PMID 4061480：该文是 Crohn's disease 患者肝脓肿/感染并发症病例，Enterobacter aerogenes 为感染分离菌，并非一般性的 IBD microbiome association，故不计 confirmed。 | K43: https://pubmed.ncbi.nlm.nih.gov/4061480/ | L43: Reverse-checked GATMDA lead; complication case report | M43: pending
A44: 43 | B44: 177 | C44: 178 | D44: Klebsiella | E44: 0.12652957 | F44: 0.057816259 | G44: 0 | H44: Supported (human broader/indirect) | I44: 36436756 | J44: Klebsiella pneumoniae 在 UC 人体样本中与疾病活动度相关；该精确物种证据可支持上一级 Klebsiella 属预测，但按分类学层级保守记为间接支持。 | K44: https://pubmed.ncbi.nlm.nih.gov/36436756/ | L44: Independent species-to-genus support | M44: broader/indirect
A45: 44 | B45: 139 | C45: 140 | D45: Enterococcus faecium | E45: 0.11983579 | F45: 0.033257111 | G45: 0 | H45: Confirmed (direct human) | I45: 39604394 | J45: 人类 multi-biome IBD 分析发现 Enterococcus faecium 在 Crohn's disease 与 UC 中均富集，构成精确物种级直接人体证据。 | K45: https://pubmed.ncbi.nlm.nih.gov/39604394/ | L45: Independent PubMed verification | M45: strict/direct
A46: 45 | B46: 143 | C46: 144 | D46: Erysipelotrichales | E46: 0.11983579 | F46: 0.03325711 | G46: 0 | H46: Confirmed (direct human) | I46: 24629344 | J46: Treatment-naive new-onset Crohn's disease 人体研究中 Erysipelotrichales 与疾病状态显著相关，构成直接人体证据。 | K46: https://pubmed.ncbi.nlm.nih.gov/24629344/ | L46: Independent PubMed verification | M46: strict/direct
A47: 46 | B47: 206 | C47: 207 | D47: Oxalobacteraceae | E47: 0.11963161 | F47: 0.037892628 | G47: 0 | H47: Supported (human broader/indirect) | I47: 35860271 | J47: 人群遗传因果推断研究支持 Oxalobacter 属与 IBD/CD 相关；对 Oxalobacteraceae 家族属于下位/上位分类群间接证据。 | K47: https://pubmed.ncbi.nlm.nih.gov/35860271/ | L47: Independent human MR; taxonomic mismatch | M47: broader/indirect
A48: 47 | B48: 253 | C48: 254 | D48: Sphingomonadaceae | E48: 0.11963161 | F48: 0.037892632 | G48: 0 | H48: Confirmed (direct human) | I48: 27418066 | J48: Crohn's disease 人体肠黏膜研究发现 advancing disease margin 的 submucosa 中 Sphingomonadaceae 明显增加，直接支持该家族与 CD 的关联。 | K48: https://pubmed.ncbi.nlm.nih.gov/27418066/ | L48: Independent PubMed verification | M48: strict/direct
A49: 48 | B49: 190 | C49: 191 | D49: Lysobacter | E49: 0.11488023 | F49: 0.037238953 | G49: 0 | H49: Confirmed (direct human) | I49: 32244928; DOI 10.3390/microorganisms8030438 | J49: 人体 Crohn's disease、ulcerative colitis 与健康对照的黏膜活检微生物组研究中，Lysobacter 被识别为 IBD 相关差异属/疾病特异性属之一，属于直接人体证据。 | K49: https://pubmed.ncbi.nlm.nih.gov/32244928/ | L49: Independent PubMed verification | M49: strict/direct
A50: 49 | B50: 233 | C50: 234 | D50: Rickettsiales | E50: 0.11488023 | F50: 0.037238962 | G50: 0 | H50: Pending / no direct human evidence verified yet | J50: 当前未核实 Rickettsiales 与 IBD 的直接人体关联。 | L50: Pending | M50: pending
A51: 50 | B51: 142 | C51: 143 | D51: Erysipelotrichaceae | E51: 0.11307451 | F51: 0.046303147 | G51: 0 | H51: Confirmed (direct human) | I51: 38105519 | J51: Crohn's disease longitudinal cohort 与健康对照的 quantile-regression 分析显示 Erysipelotrichaceae 等家族与 CD/疾病过程存在显著关联，属于精确家族级人体证据。 | K51: https://pubmed.ncbi.nlm.nih.gov/38105519/ | L51: Independent PubMed verification | M51: strict/direct

Sheet IBD_all
A1: rank | B1: microbe_index_0based | C1: microbe_id | D1: microbe_name | E1: score_mean | F1: score_std | G1: originally_known_in_HMDAD | H1: literature_status | I1: PMID_or_DOI | J1: evidence_notes | K1: source_url | L1: evidence_basis | M1: verification_scope
A2: 1 | B2: 108 | C2: 109 | D2: Clostridium difficile | E2: 0.64931703 | F2: 0.063818269 | G2: 0 | H2: Confirmed (direct human) | I2: 18513271 | J2: IBD 人群中 C. difficile 感染/定植显著相关，尤其在 UC 中常见。 | K2: https://pubmed.ncbi.nlm.nih.gov/18513271/ | L2: Independent PubMed verification | M2: strict/direct
A3: 2 | B3: 106 | C3: 107 | D3: Clostridium coccoides | E3: 0.63173096 | F3: 0.058970483 | G3: 0 | H3: Confirmed (direct human) | I3: 22092917; GATMDA lead PMID 19235886 | J3: 人体 IBD/UC 研究报告 C. coccoides group 明显减少。 | K3: https://pubmed.ncbi.nlm.nih.gov/22092917/ | L3: Independent PubMed verification + GATMDA lead | M3: strict/direct
A4: 3 | B4: 60 | C4: 61 | D4: Bacteroidetes | E4: 0.61293416 | F4: 0.057358029 | G4: 0 | H4: Confirmed (direct human) | I4: 33738265 | J4: IBD 人体肠道宏基因组研究报道 Bacteroidetes 组成显著改变。 | K4: https://pubmed.ncbi.nlm.nih.gov/33738265/ | L4: Independent PubMed verification | M4: strict/direct
A5: 4 | B5: 4 | C5: 5 | D5: Actinobacteria | E5: 0.58516245 | F5: 0.06589116 | G5: 1 | H5: Confirmed (direct human) | I5: 33738265 | J5: IBD 人体肠道宏基因组研究支持 Actinobacteria 组成变化。 | K5: https://pubmed.ncbi.nlm.nih.gov/33738265/ | L5: Independent PubMed verification | M5: strict/direct
A6: 5 | B6: 93 | C6: 94 | D6: Clostridia | E6: 0.5297197 | F6: 0.046664697 | G6: 0 | H6: Confirmed (direct human) | I6: 31142855 | J6: 纵向 multi-omics 人体 IBD 研究显示疾病活动伴随 clostridia 的系统性分子/群落扰动，直接支持 Clostridia–IBD 关联。 | K6: https://pubmed.ncbi.nlm.nih.gov/31142855/ | L6: Independent PubMed verification | M6: strict/direct
A7: 6 | B7: 154 | C7: 155 | D7: Firmicutes | E7: 0.50680436 | F7: 0.11248417 | G7: 0 | H7: Confirmed (direct human) | I7: 33738265; GATMDA lead PMID 25307765 | J7: IBD 人体研究中 Firmicutes 显著改变；GATMDA Table 5 也给出 PMID 25307765。 | K7: https://pubmed.ncbi.nlm.nih.gov/33738265/ | L7: Independent PubMed verification + GATMDA lead | M7: strict/direct
A8: 7 | B8: 230 | C8: 231 | D8: Proteobacteria | E8: 0.49374721 | F8: 0.11887946 | G8: 1 | H8: Confirmed (direct human) | I8: 33738265 | J8: IBD 人体肠道研究支持 Proteobacteria 增加/失衡。 | K8: https://pubmed.ncbi.nlm.nih.gov/33738265/ | L8: Independent PubMed verification | M8: strict/direct
A9: 8 | B9: 224 | C9: 225 | D9: Prevotella | E9: 0.47112395 | F9: 0.11208429 | G9: 0 | H9: Confirmed (direct human) | I9: 34620880; GATMDA lead PMID 25307765 | J9: 人体 IBD 数据显示 Prevotella 组成与 IBD 状态相关。 | K9: https://pubmed.ncbi.nlm.nih.gov/34620880/ | L9: Independent PubMed verification + GATMDA lead | M9: strict/direct
A10: 9 | B10: 168 | C10: 169 | D10: Helicobacter pylori | E10: 0.46937895 | F10: 0.11407409 | G10: 0 | H10: Confirmed (direct human) | I10: 37682136; GATMDA lead PMID 22221289 | J10: 人体研究支持 H. pylori 与 IBD 的负向/保护性关联；负向也属于 association。 | K10: https://pubmed.ncbi.nlm.nih.gov/37682136/ | L10: Independent PubMed verification + GATMDA lead | M10: strict/direct
A11: 10 | B11: 110 | C11: 111 | D11: Clostridium leptum | E11: 0.46524679 | F11: 0.077642731 | G11: 0 | H11: Confirmed (direct human) | I11: 22092917; GATMDA lead PMID 28099495 | J11: 人体 IBD/UC 研究报告 C. leptum group 减少。 | K11: https://pubmed.ncbi.nlm.nih.gov/22092917/ | L11: Independent PubMed verification + GATMDA lead | M11: strict/direct
A12: 11 | B12: 255 | C12: 256 | D12: Staphylococcus aureus | E12: 0.42097209 | F12: 0.11661842 | G12: 0 | H12: Confirmed (direct human) | I12: 11424320 | J12: IBD 患者肠黏膜中检测到 S. aureus，并与疾病状态相关。 | K12: https://pubmed.ncbi.nlm.nih.gov/11424320/ | L12: Independent PubMed verification | M12: strict/direct
A13: 12 | B13: 68 | C13: 69 | D13: Burkholderia | E13: 0.39792757 | F13: 0.093858679 | G13: 0 | H13: Confirmed (direct human) | I13: 39187879 | J13: UC 人体纵向研究中 Burkholderia-Caballeronia-Paraburkholderia 与疾病/缓解状态相关。 | K13: https://pubmed.ncbi.nlm.nih.gov/39187879/ | L13: Independent PubMed verification | M13: strict/direct
... A30: 29 | B30: 2 | C30: 3 | D30: Acinetobacter | E30: 0.21503316 | F30: 0.054474599 | G30: 0 | H30: Confirmed (direct human) | I30: 25559083 | J30: 人体 colitis 组织研究发现 Acinetobacter 等菌在 actively inflamed colitis tissue 中富集，属于直接人体 IBD/colitis 关联证据。 | K30: https://pubmed.ncbi.nlm.nih.gov/25559083/ | L30: Independent PubMed verification | M30: strict/direct
A31: 30 | B31: 120 | C31: 121 | D31: Coxiellaceae | E31: 0.19113614 | F31: 0.045546413 | G31: 0 | H31: Pending / no direct human evidence verified yet | J31: 当前未独立核实 Coxiellaceae 与 IBD 的直接人体关联。 | L31: Pending | M31: pending
A32: 31 | B32: 5 | C32: 6 | D32: Actinomyces | E32: 0.18773857 | F32: 0.065629591 | G32: 0 | H32: Confirmed (direct human) | I32: 30545401 | J32: 人体病例-对照肠道微生物研究比较 Crohn's disease、UC 与健康对照，Actinomyces 在疾病队列中显著改变，直接支持该关联。 | K32: https://pubmed.ncbi.nlm.nih.gov/30545401/ | L32: Independent PubMed verification | M32: strict/direct
A33: 32 | B33: 159 | C33: 160 | D33: Fusobacterium | E33: 0.1785091 | F33: 0.057557866 | G33: 0 | H33: Confirmed (direct human) | I33: 39273567; GATMDA lead PMID 25307765 | J33: 人体 IBD 微生物组研究支持 Fusobacterium 与疾病相关；GATMDA Table 5 也列出证据。 | K33: https://pubmed.ncbi.nlm.nih.gov/39273567/ | L33: Independent PubMed verification + GATMDA lead | M33: strict/direct
A34: 33 | B34: 114 | C34: 115 | D34: Collinsella aerofaciens | E34: 0.17718287 | F34: 0.04004577 | G34: 0 | H34: Supported (human broader/indirect) | I34: 21209126 | J34: Crohn's disease、未患病一级亲属及健康对照的人体研究检测到 Collinsella aerofaciens 差异，但主要信号出现在未患病亲属而非直接 CD 病例效应，因此保守记为间接支持。 | K34: https://pubmed.ncbi.nlm.nih.gov/21209126/ | L34: Independent human study; indirect disease-context evidence | M34: broader/indirect
A35: 34 | B35: 153 | C35: 154 | D35: Faecalibacterium prausnitzii | E35: 0.1670976 | F35: 0.071529776 | G35: 0 | H35: Confirmed (direct human) | I35: 18936492 | J35: 经典 Crohn's disease 人体研究显示 Faecalibacterium prausnitzii 在患者中减少，并与术后复发相关，构成直接人体证据。 | K35: https://pubmed.ncbi.nlm.nih.gov/18936492/ | L35: Independent PubMed verification | M35: strict/direct
A36: 35 | B36: 62 | C36: 63 | D36: Bifidobacterium | E36: 0.16025481 | F36: 0.05786736 | G36: 0 | H36: Confirmed (direct human) | I36: 38779566; GATMDA lead PMID 24478468 | J36: UC 与健康对照研究中 Bifidobacterium 显著改变。 | K36: https://pubmed.ncbi.nlm.nih.gov/38779566/ | L36: Independent PubMed verification + GATMDA lead | M36: strict/direct
A37: 36 | B37: 161 | C37: 162 | D37: Gammaproteobacteria | E37: 0.15023371 | F37: 0.054084768 | G37: 0 | H37: Supported (human broader/indirect) | I37: 33738265 | J37: IBD 人体研究支持 Proteobacteria/Gammaproteobacteria 相关失衡；对该精确 class 的效应保守记为 broader。 | K37: https://pubmed.ncbi.nlm.nih.gov/33738265/ | L37: Independent broader taxon | M37: broader/indirect
A38: 37 | B38: 226 | C38: 227 | D38: Prevotellaceae | E38: 0.13810329 | F38: 0.059789613 | G38: 0 | H38: Supported (human broader/indirect) | I38: 39806416 | J38: 人体 IBD 研究支持 Prevotellaceae 相关菌群/代谢轴与 IBD 相关，证据偏机制/关联链条。 | K38: https://pubmed.ncbi.nlm.nih.gov/39806416/ | L38: Independent human broader evidence | M38: broader/indirect
A39: 38 | B39: 262 | C39: 263 | D39: Streptococcus mitis | E39: 0.13710661 | F39: 0.050481713 | G39: 0 | H39: Confirmed (direct human) | I39: 40854688 | J39: UC 人体黏膜微生物组研究中，吸烟与 Streptococcus mitis 等口源菌在结肠黏膜的异位增加相关，属于 IBD 疾病背景下的精确物种人体证据。 | K39: https://pubmed.ncbi.nlm.nih.gov/40854688/ | L39: Independent PubMed verification | M39: strict/direct
A40: 39 | B40: 250 | C40: 251 | D40: Shigella dysenteriae | E40: 0.13304512 | F40: 0.043353917 | G40: 0 | H40: Pending / no direct human evidence verified yet | J40: GATMDA Table 5 对 Shigella dysenteriae–IBD 标为 unconfirmed。 | L40: GATMDA Table 5: unconfirmed | M40: pending
A41: 40 | B41: 178 | C41: 179 | D41: Klebsiella pneumoniae | E41: 0.13304511 | F41: 0.043353899 | G41: 0 | H41: Confirmed (direct human) | I41: 36436756 | J41: 人体 UC 样本中 Klebsiella pneumoniae 与 Mayo disease activity index 呈正相关，并从 colitis 患者结肠组织分离菌株；后续机制实验进一步验证其致炎作用。 | K41: https://pubmed.ncbi.nlm.nih.gov/36436756/ | L41: Independent human + mechanistic verification | M41: strict/direct
A42: 41 | B42: 135 | C42: 136 | D42: Enterobacter hormaechei | E42: 0.13304511 | F42: 0.043353901 | G42: 0 | H42: Supported (human broader/indirect) | I42: 22837318 | J42: 新诊断儿童 Crohn's disease 人体病例-对照研究检测到 Enterobacter hormaechei，病例检出率高于对照但未达到传统显著性（P≈0.059），故记为人体间接/趋势性支持。 | K42: https://pubmed.ncbi.nlm.nih.gov/22837318/ | L42: Independent human study; non-significant trend | M42: broader/indirect
A43: 42 | B43: 134 | C43: 135 | D43: Enterobacter aerogenes | E43: 0.13304511 | F43: 0.043353901 | G43: 0 | H43: Pending / no direct human evidence verified yet | I43: 4061480 | J43: 反查 GATMDA 所列 PMID 4061480：该文是 Crohn's disease 患者肝脓肿/感染并发症病例，Enterobacter aerogenes 为感染分离菌，并非一般性的 IBD microbiome association，故不计 confirmed。 | K43: https://pubmed.ncbi.nlm.nih.gov/4061480/ | L43: Reverse-checked GATMDA lead; complication case report | M43: pending
A44: 43 | B44: 177 | C44: 178 | D44: Klebsiella | E44: 0.12652957 | F44: 0.057816259 | G44: 0 | H44: Supported (human broader/indirect) | I44: 36436756 | J44: Klebsiella pneumoniae 在 UC 人体样本中与疾病活动度相关；该精确物种证据可支持上一级 Klebsiella 属预测，但按分类学层级保守记为间接支持。 | K44: https://pubmed.ncbi.nlm.nih.gov/36436756/ | L44: Independent species-to-genus support | M44: broader/indirect
A45: 44 | B45: 139 | C45: 140 | D45: Enterococcus faecium | E45: 0.11983579 | F45: 0.033257111 | G45: 0 | H45: Confirmed (direct human) | I45: 39604394 | J45: 人类 multi-biome IBD 分析发现 Enterococcus faecium 在 Crohn's disease 与 UC 中均富集，构成精确物种级直接人体证据。 | K45: https://pubmed.ncbi.nlm.nih.gov/39604394/ | L45: Independent PubMed verification | M45: strict/direct
A46: 45 | B46: 143 | C46: 144 | D46: Erysipelotrichales | E46: 0.11983579 | F46: 0.03325711 | G46: 0 | H46: Confirmed (direct human) | I46: 24629344 | J46: Treatment-naive new-onset Crohn's disease 人体研究中 Erysipelotrichales 与疾病状态显著相关，构成直接人体证据。 | K46: https://pubmed.ncbi.nlm.nih.gov/24629344/ | L46: Independent PubMed verification | M46: strict/direct
A47: 46 | B47: 206 | C47: 207 | D47: Oxalobacteraceae | E47: 0.11963161 | F47: 0.037892628 | G47: 0 | H47: Supported (human broader/indirect) | I47: 35860271 | J47: 人群遗传因果推断研究支持 Oxalobacter 属与 IBD/CD 相关；对 Oxalobacteraceae 家族属于下位/上位分类群间接证据。 | K47: https://pubmed.ncbi.nlm.nih.gov/35860271/ | L47: Independent human MR; taxonomic mismatch | M47: broader/indirect
A48: 47 | B48: 253 | C48: 254 | D48: Sphingomonadaceae | E48: 0.11963161 | F48: 0.037892632 | G48: 0 | H48: Confirmed (direct human) | I48: 27418066 | J48: Crohn's disease 人体肠黏膜研究发现 advancing disease margin 的 submucosa 中 Sphingomonadaceae 明显增加，直接支持该家族与 CD 的关联。 | K48: https://pubmed.ncbi.nlm.nih.gov/27418066/ | L48: Independent PubMed verification | M48: strict/direct
A49: 48 | B49: 190 | C49: 191 | D49: Lysobacter | E49: 0.11488023 | F49: 0.037238953 | G49: 0 | H49: Confirmed (direct human) | I49: 32244928; DOI 10.3390/microorganisms8030438 | J49: 人体 Crohn's disease、ulcerative colitis 与健康对照的黏膜活检微生物组研究中，Lysobacter 被识别为 IBD 相关差异属/疾病特异性属之一，属于直接人体证据。 | K49: https://pubmed.ncbi.nlm.nih.gov/32244928/ | L49: Independent PubMed verification | M49: strict/direct
A50: 49 | B50: 233 | C50: 234 | D50: Rickettsiales | E50: 0.11488023 | F50: 0.037238962 | G50: 0 | H50: Pending / no direct human evidence verified yet | J50: 当前未核实 Rickettsiales 与 IBD 的直接人体关联。 | L50: Pending | M50: pending
A51: 50 | B51: 142 | C51: 143 | D51: Erysipelotrichaceae | E51: 0.11307451 | F51: 0.046303147 | G51: 0 | H51: Confirmed (direct human) | I51: 38105519 | J51: Crohn's disease longitudinal cohort 与健康对照的 quantile-regression 分析显示 Erysipelotrichaceae 等家族与 CD/疾病过程存在显著关联，属于精确家族级人体证据。 | K51: https://pubmed.ncbi.nlm.nih.gov/38105519/ | L51: Independent PubMed verification | M51: strict/direct
A52: 51 | B52: 194 | C52: 195 | D52: Methanobrevibacter smithii | E52: 0.11307451 | F52: 0.046303144 | G52: 0
A53: 52 | B53: 290 | C53: 291 | D53: Xanthomonas | E53: 0.11253983 | F53: 0.046386123 | G53: 0
A54: 53 | B54: 228 | C54: 229 | D54: Propionibacterium | E54: 0.11183742 | F54: 0.030537483 | G54: 0
A55: 54 | B55: 229 | C55: 230 | D55: Propionibacterium acnes | E55: 0.11183742 | F55: 0.030537483 | G55: 0
A56: 55 | B56: 247 | C56: 248 | D56: Selenomonas | E56: 0.11037127 | F56: 0.037519123 | G56: 0
...

Sheet Literature_summary
A1: 案例研究：文献验证进度汇总
A3: Disease | B3: Top K | C3: Independent Confirmed | D3: Confirmed + Broader Support | E3: GATMDA PMID Leads (pending reverse-check) | F3: Pending/Unverified | G3: Support Rate (broad) | H3: GATMDA paper reported
A4: Asthma | B4: 10 | C4: =COUNTIF(Asthma_top50!$H$2:$H$11,"Confirmed (direct human)") -> 10 | D4: =COUNTIF(Asthma_top50!$H$2:$H$11,"Confirmed (direct human)")+COUNTIF(Asthma_top50!$H$2:$H$11,"Supported (human broader/indirect)") -> 10 | E4: =COUNTIF(Asthma_top50!$H$2:$H$11,"GATMDA-reported lead; needs reverse-check") -> 0 | F4: =COUNTIF(Asthma_top50!$H$2:$H$11,"Pending / no direct human evidence verified yet") -> 0 | G4: =D4/B4 -> 1 | H4: 10
A5: Asthma | B5: 20 | C5: =COUNTIF(Asthma_top50!$H$2:$H$21,"Confirmed (direct human)") -> 18 | D5: =COUNTIF(Asthma_top50!$H$2:$H$21,"Confirmed (direct human)")+COUNTIF(Asthma_top50!$H$2:$H$21,"Supported (human broader/indirect)") -> 19 | E5: =COUNTIF(Asthma_top50!$H$2:$H$21,"GATMDA-reported lead; needs reverse-check") -> 0 | F5: =COUNTIF(Asthma_top50!$H$2:$H$21,"Pending / no direct human evidence verified yet") -> 1 | G5: =D5/B5 -> 0.95 | H5: 18
A6: Asthma | B6: 50 | C6: =COUNTIF(Asthma_top50!$H$2:$H$51,"Confirmed (direct human)") -> 30 | D6: =COUNTIF(Asthma_top50!$H$2:$H$51,"Confirmed (direct human)")+COUNTIF(Asthma_top50!$H$2:$H$51,"Supported (human broader/indirect)") -> 44 | E6: =COUNTIF(Asthma_top50!$H$2:$H$51,"GATMDA-reported lead; needs reverse-check") -> 0 | F6: =COUNTIF(Asthma_top50!$H$2:$H$51,"Pending / no direct human evidence verified yet") -> 6 | G6: =D6/B6 -> 0.88 | H6: 38
A7: IBD | B7: 10 | C7: =COUNTIF(IBD_top50!$H$2:$H$11,"Confirmed (direct human)") -> 10 | D7: =COUNTIF(IBD_top50!$H$2:$H$11,"Confirmed (direct human)")+COUNTIF(IBD_top50!$H$2:$H$11,"Supported (human broader/indirect)") -> 10 | E7: =COUNTIF(IBD_top50!$H$2:$H$11,"GATMDA-reported lead; needs reverse-check") -> 0 | F7: =COUNTIF(IBD_top50!$H$2:$H$11,"Pending / no direct human evidence verified yet") -> 0 | G7: =D7/B7 -> 1 | H7: 10
A8: IBD | B8: 20 | C8: =COUNTIF(IBD_top50!$H$2:$H$21,"Confirmed (direct human)") -> 18 | D8: =COUNTIF(IBD_top50!$H$2:$H$21,"Confirmed (direct human)")+COUNTIF(IBD_top50!$H$2:$H$21,"Supported (human broader/indirect)") -> 20 | E8: =COUNTIF(IBD_top50!$H$2:$H$21,"GATMDA-reported lead; needs reverse-check") -> 0 | F8: =COUNTIF(IBD_top50!$H$2:$H$21,"Pending / no direct human evidence verified yet") -> 0 | G8: =D8/B8 -> 1 | H8: 20
A9: IBD | B9: 50 | C9: =COUNTIF(IBD_top50!$H$2:$H$51,"Confirmed (direct human)") -> 38 | D9: =COUNTIF(IBD_top50!$H$2:$H$51,"Confirmed (direct human)")+COUNTIF(IBD_top50!$H$2:$H$51,"Supported (human broader/indirect)") -> 46 | E9: =COUNTIF(IBD_top50!$H$2:$H$51,"GATMDA-reported lead; needs reverse-check") -> 0 | F9: =COUNTIF(IBD_top50!$H$2:$H$51,"Pending / no direct human evidence verified yet") -> 4 | G9: =D9/B9 -> 0.92 | H9: 44
A11: 判定规则 / 重要说明
A12: Confirmed (direct human) | B12: 至少一篇可核实的人体原始研究直接支持该精确/合理匹配分类群与疾病状态、风险、严重度、丰度或定植之间的关联。
A13: Supported (human broader/indirect) | B13: 有人体证据，但属于上/下位分类群、疾病表型、临床分离株、MR 或其他较间接证据；不计入最严格 confirmed。
A14: GATMDA-reported lead; needs reverse-check | B14: GATMDA Table 4/5 给出了 PMID，但本项目尚未逐 PMID 独立反查；不能直接当作最终 confirmed。
A15: Pending / no direct human evidence verified yet | B15: 当前尚未核实到足够直接的人体证据；这不是宣称不存在，只表示本轮检索未完成/未找到。
A17: 注意：GATMDA 报告的 Asthma 10/20/50 confirmed 数为 10/18/38，IBD 为 10/20/44；这些数字仅作参考。我们采用更严格的“独立反查 PMID”流程，因此在 lead-only 项完成反查前，不应直接比较最终确认率。
A19: 本轮复核新增说明
A20: 本表采用“逐 PMID 反查”而非直接复用 GATMDA Table 4/5 的 Evidence。若原 PMID 与预测关系不直接匹配，则降级为 Pending/Indirect，并在 Citation_Audit 中记录。
A21: 因此最终确认率应以本工作簿中的 Independent Confirmed / Confirmed + Broader Support 为准，而不是机械复制 GATMDA 的 38/50、44/50。
A22: 最终复核状态
A23: 截至本轮，Top50 中所有原先标记为 GATMDA PMID lead-only 的条目均已完成反查；剩余 Pending 项均为本轮未核实到足够直接人体证据的真实未确认项。
A24: 因此可同时报告“strict direct-human confirmation”与“direct + broader human support”两套数字，并明确二者判定标准。

Sheet Citation_Audit
A1: Disease | B1: Predicted microbe | C1: GATMDA PMID | D1: Reverse-check conclusion | E1: Decision in our study | F1: Source URL
A2: Asthma | B2: Escherichia coli | C2: 29161804 | D2: Not a direct human E. coli–asthma association; focuses on microbial extracellular vesicles/chronic lung inflammation and experimental evidence. | E2: Do not count as confirmed. | F2: https://pubmed.ncbi.nlm.nih.gov/29161804/
A3: Asthma | B3: Enterobacter aerogenes | C3: 23842440 | D3: Citation mismatch: paper is about Fagonia olivieri phytochemical/antimicrobial activity, not asthma association. | E3: Do not count as confirmed. | F3: https://pubmed.ncbi.nlm.nih.gov/23842440/
A4: IBD | B4: Klebsiella pneumoniae | C4: 9930068 | D4: Paper reports absence/lack of support for these bacterial antigens in IBD tissue rather than a positive association. | E4: Replace with stronger human evidence PMID 36436756. | F4: https://pubmed.ncbi.nlm.nih.gov/9930068/
A5: IBD | B5: Enterobacter aerogenes | C5: 4061480 | D5: Crohn's disease liver-abscess/infection complication case report; not a general IBD microbiome association. | E5: Do not count as confirmed. | F5: https://pubmed.ncbi.nlm.nih.gov/4061480/

Sheet Remaining_Pending
A1: Disease | B1: Rank | C1: Microbe | D1: Current status | E1: Search conclusion | F1: Why not counted as confirmed | G1: Representative search/source
A2: Asthma | B2: 31 | C2: Shigella dysenteriae | D2: Pending | E2: 检索到的是感染性痢疾/肠炎文献，未核实到 asthma 患者中的直接微生物关联研究。 | F2: 感染性疾病证据不能替代 asthma association。 | G2: PubMed exact-species asthma searches; no direct human asthma paper verified
A3: Asthma | B3: 32 | C3: Enterobacter aerogenes (Klebsiella aerogenes) | D3: Pending | E3: GATMDA 的 PMID 23842440 反查为植物提取物抗菌研究；按新名称 K. aerogenes 检索也未找到直接 asthma 人体关联。 | F3: 原 PMID 错配；其余结果不是 asthma association。 | G3: https://pubmed.ncbi.nlm.nih.gov/23842440/
A4: Asthma | B4: 33 | C4: Enterobacter hormaechei | D4: Pending | E4: 主要检索到计算预测论文或其他呼吸疾病研究，未核实到直接 asthma 人体病例-对照/队列证据。 | F4: 计算预测不能作为外部生物医学确认。 | G4: https://pubmed.ncbi.nlm.nih.gov/37789848/
A5: Asthma | B5: 46 | C5: Lysobacter | D5: Pending | E5: 检索到环境暴露、CF/其他肺病以及综述性提及；未核实到直接的人体 asthma Lysobacter association。 | F5: 环境/其他疾病/综述不能作为严格确认。 | G5: Human-asthma exact-taxon searches; no direct paper verified
A6: Asthma | B6: 50 | C6: Dietzia maris | D6: Pending | E6: 可核实文献主要为机会性感染、atopic dermatitis/环境研究，未找到直接 asthma 人体关联。 | F6: 相邻过敏表型不等同于 asthma。 | G6: Human-asthma exact-species searches; no direct paper verified
A7: IBD | B7: 30 | C7: Coxiellaceae | D7: Pending | E7: 未核实到 Coxiellaceae 与 Crohn's disease/UC 的直接人体关联研究。 | F7: 检索结果多为非 IBD 人群或动物/环境研究。 | G7: Human IBD exact-family searches; no direct paper verified
A8: IBD | B8: 39 | C8: Shigella dysenteriae | D8: Pending | E8: 存在大量 Shigella dysenteriae 引起急性感染性 colitis 的人体研究，但这不是慢性 Crohn's disease/UC 微生物关联。 | F8: infectious colitis 可模拟 IBD，但不能算 IBD association。 | G8: https://pubmed.ncbi.nlm.nih.gov/3535768/
A9: IBD | B9: 42 | C9: Enterobacter aerogenes (Klebsiella aerogenes) | D9: Pending | E9: GATMDA PMID 4061480 是 Crohn 患者肝脓肿/感染并发症病例；2025 K. aerogenes enteritis 研究主要是动物机制，不满足直接人体 IBD 标准。 | F9: 并发感染病例/动物机制不足以确认一般 IBD association。 | G9: https://pubmed.ncbi.nlm.nih.gov/4061480/
